Workbook

Sheet Information
A1: Household Water Use Data
A3: Instructions: | C3: Fill in the yellow cells in the "Information" and "Data" worksheets. Delete any example data. Estimate where needed, and leave a note on on the method.
A5: Water Provider/ Utility Name: | D5: City of Westminster | K5: What is the official name of the water provider?
A6: Units of Volume: | D6: thousand gallons (kgal) | F6: What units are you reporting in?
C7: Service Area Size: | D7: Population of ~135,000 | G7: Will you somehow send us your service area boundary (as a shapefile perhaps)?
C8: Notes: | D8: See shapefiles for download at: https://opendata-westminster.hub.arcgis.com/ - view map of service area in Water Conservation & Efficiency Plan (avail on main city website) Water utility service area includes all properties within City of Westminster, Shaw Heights, enclave properties of unicorporated Jefferson and Adams Counties, and all of Federal Heights. | K8: Tell us about any nuances of the data you foresee being a problem… Or, what you might think could be an interesting outcome of this research that would benefit your organization…
L13: "Population" is the served population within the service boundary, and if there are large fluctuations of served
L14: populations throughout the year (tourists, students, etc.), provide the average number of people being served
A15: Contact Name: | D15: Drew Beckwith | L15: each day of the year.
A16: Contact Email: | D16: dbeckwith@westminsterco.gov | L16: Yearly Summary
L17: Year | M17: Served (Westminster + Shaw Heights + Enclaves) | N17: Served (Federal Heights) | P17: Total Households | Q17: ="Water Used (" & D6 & ")" -> Water Used (thousand gallons (kgal))
A18: Information about the data requested: | O18: Total Served Population | Q18: Residential Single Family | R18: Residential Multi Family | S18: SF and MF Residential Combined | T18: Total Use
L19: 2013 | Q19: {=SUMPRODUCT(Data!$C$2:$C$10001,--(Data!$D$2:$D$10001=Information!Q$18),--(YEAR(Data!$B$2:$B$10001)=Information!$L19))} -> 0 | R19: {=SUMPRODUCT(Data!$C$2:$C$10001,--(Data!$D$2:$D$10001=Information!R$18),--(YEAR(Data!$B$2:$B$10001)=Information!$L19))} -> 0 | S19: {=SUMPRODUCT(Data!$C$2:$C$10001,--(Data!$D$2:$D$10001=Information!S$18),--(YEAR(Data!$B$2:$B$10001)=Information!$L19))} -> 0 | T19: =SUM(Q19:S19) -> 0
A20: We are looking to collect billing data for households within your service area. Data collected before, during, and after a rate change is especially valuable. Only water use will be requested; no identifying data will be required. | L20: 2014 | Q20: {=SUMPRODUCT(Data!$C$2:$C$10001,--(Data!$D$2:$D$10001=Information!Q$18),--(YEAR(Data!$B$2:$B$10001)=Information!$L20))} -> 0 | R20: {=SUMPRODUCT(Data!$C$2:$C$10001,--(Data!$D$2:$D$10001=Information!R$18),--(YEAR(Data!$B$2:$B$10001)=Information!$L20))} -> 0 | S20: {=SUMPRODUCT(Data!$C$2:$C$10001,--(Data!$D$2:$D$10001=Information!S$18),--(YEAR(Data!$B$2:$B$10001)=Information!$L20))} -> 0 | T20: =SUM(Q20:S20) -> 0
L21: 2015 | M21: 118288 | N21: 12487 | O21: =M21+N21 -> 130775 | P21: Could use data within #Units column or summary table at bottom, to determine by year | Q21: {=SUMPRODUCT(Data!$C$2:$C$10001,--(Data!$D$2:$D$10001=Information!Q$18),--(YEAR(Data!$B$2:$B$10001)=Information!$L21))} -> 0 | R21: {=SUMPRODUCT(Data!$C$2:$C$10001,--(Data!$D$2:$D$10001=Information!R$18),--(YEAR(Data!$B$2:$B$10001)=Information!$L21))} -> 0 | S21: {=SUMPRODUCT(Data!$C$2:$C$10001,--(Data!$D$2:$D$10001=Information!S$18),--(YEAR(Data!$B$2:$B$10001)=Information!$L21))} -> 0 | T21: =SUM(Q21:S21) -> 0
L22: 2016 | M22: 119013 | N22: 12665 | O22: =M22+N22 -> 131678 | Q22: {=SUMPRODUCT(Data!$C$2:$C$10001,--(Data!$D$2:$D$10001=Information!Q$18),--(YEAR(Data!$B$2:$B$10001)=Information!$L22))} -> 0 | R22: {=SUMPRODUCT(Data!$C$2:$C$10001,--(Data!$D$2:$D$10001=Information!R$18),--(YEAR(Data!$B$2:$B$10001)=Information!$L22))} -> 0 | S22: {=SUMPRODUCT(Data!$C$2:$C$10001,--(Data!$D$2:$D$10001=Information!S$18),--(YEAR(Data!$B$2:$B$10001)=Information!$L22))} -> 0 | T22: =SUM(Q22:S22) -> 0
L23: 2017 | M23: 119027 | N23: 12744 | O23: =M23+N23 -> 131771 | Q23: {=SUMPRODUCT(Data!$C$2:$C$10001,--(Data!$D$2:$D$10001=Information!Q$18),--(YEAR(Data!$B$2:$B$10001)=Information!$L23))} -> 0 | R23: {=SUMPRODUCT(Data!$C$2:$C$10001,--(Data!$D$2:$D$10001=Information!R$18),--(YEAR(Data!$B$2:$B$10001)=Information!$L23))} -> 0 | S23: {=SUMPRODUCT(Data!$C$2:$C$10001,--(Data!$D$2:$D$10001=Information!S$18),--(YEAR(Data!$B$2:$B$10001)=Information!$L23))} -> 0 | T23: =SUM(Q23:S23) -> 0
A24: We are requesting that data shared with us contain the following at minimum: | L24: 2018 | M24: 119739 | N24: 12744 | O24: =M24+N24 -> 132483 | Q24: {=SUMPRODUCT(Data!$C$2:$C$10001,--(Data!$D$2:$D$10001=Information!Q$18),--(YEAR(Data!$B$2:$B$10001)=Information!$L24))} -> 0 | R24: {=SUMPRODUCT(Data!$C$2:$C$10001,--(Data!$D$2:$D$10001=Information!R$18),--(YEAR(Data!$B$2:$B$10001)=Information!$L24))} -> 0 | S24: {=SUMPRODUCT(Data!$C$2:$C$10001,--(Data!$D$2:$D$10001=Information!S$18),--(YEAR(Data!$B$2:$B$10001)=Information!$L24))} -> 0 | T24: =SUM(Q24:S24) -> 0
L25: 2019 | M25: 119721 | N25: 12845 | O25: =M25+N25 -> 132566 | Q25: {=SUMPRODUCT(Data!$C$2:$C$10001,--(Data!$D$2:$D$10001=Information!Q$18),--(YEAR(Data!$B$2:$B$10001)=Information!$L25))} -> 0 | R25: {=SUMPRODUCT(Data!$C$2:$C$10001,--(Data!$D$2:$D$10001=Information!R$18),--(YEAR(Data!$B$2:$B$10001)=Information!$L25))} -> 0 | S25: {=SUMPRODUCT(Data!$C$2:$C$10001,--(Data!$D$2:$D$10001=Information!S$18),--(YEAR(Data!$B$2:$B$10001)=Information!$L25))} -> 0 | T25: =SUM(Q25:S25) -> 0
B26: Household Reference Number: Each household should be assigned their own, new number that will be used to distinguish one household’s usage from another. This number should not be in any way connected to any existing identifier codes used by the provider for their own internal tracking. | L26: 2020 | M26: 119823.75 | N26: 12827 | O26: =M26+N26 -> 132650.75 | Q26: {=SUMPRODUCT(Data!$C$2:$C$10001,--(Data!$D$2:$D$10001=Information!Q$18),--(YEAR(Data!$B$2:$B$10001)=Information!$L26))} -> 0 | R26: {=SUMPRODUCT(Data!$C$2:$C$10001,--(Data!$D$2:$D$10001=Information!R$18),--(YEAR(Data!$B$2:$B$10001)=Information!$L26))} -> 0 | S26: {=SUMPRODUCT(Data!$C$2:$C$10001,--(Data!$D$2:$D$10001=Information!S$18),--(YEAR(Data!$B$2:$B$10001)=Information!$L26))} -> 0 | T26: =SUM(Q26:S26) -> 0
L27: 2021 | M27: 122631 | N27: 14382 | O27: =M27+N27 -> 137013 | Q27: {=SUMPRODUCT(Data!$C$2:$C$10001,--(Data!$D$2:$D$10001=Information!Q$18),--(YEAR(Data!$B$2:$B$10001)=Information!$L27))} -> 0 | R27: {=SUMPRODUCT(Data!$C$2:$C$10001,--(Data!$D$2:$D$10001=Information!R$18),--(YEAR(Data!$B$2:$B$10001)=Information!$L27))} -> 0 | S27: {=SUMPRODUCT(Data!$C$2:$C$10001,--(Data!$D$2:$D$10001=Information!S$18),--(YEAR(Data!$B$2:$B$10001)=Information!$L27))} -> 0 | T27: =SUM(Q27:S27) -> 0
L28: 2022 | M28: 122689 | N28: 14432 | O28: =M28+N28 -> 137121 | Q28: {=SUMPRODUCT(Data!$C$2:$C$10001,--(Data!$D$2:$D$10001=Information!Q$18),--(YEAR(Data!$B$2:$B$10001)=Information!$L28))} -> 0 | R28: {=SUMPRODUCT(Data!$C$2:$C$10001,--(Data!$D$2:$D$10001=Information!R$18),--(YEAR(Data!$B$2:$B$10001)=Information!$L28))} -> 0 | S28: {=SUMPRODUCT(Data!$C$2:$C$10001,--(Data!$D$2:$D$10001=Information!S$18),--(YEAR(Data!$B$2:$B$10001)=Information!$L28))} -> 0 | T28: =SUM(Q28:S28) -> 0
L29: 2023 | M29: 120814 | N29: 14001 | O29: =M29+N29 -> 134815 | Q29: {=SUMPRODUCT(Data!$C$2:$C$10001,--(Data!$D$2:$D$10001=Information!Q$18),--(YEAR(Data!$B$2:$B$10001)=Information!$L29))} -> 0 | R29: {=SUMPRODUCT(Data!$C$2:$C$10001,--(Data!$D$2:$D$10001=Information!R$18),--(YEAR(Data!$B$2:$B$10001)=Information!$L29))} -> 0 | S29: {=SUMPRODUCT(Data!$C$2:$C$10001,--(Data!$D$2:$D$10001=Information!S$18),--(YEAR(Data!$B$2:$B$10001)=Information!$L29))} -> 0 | T29: =SUM(Q29:S29) -> 0
L30: 2024 | M30: 121212.83 | N30: 13943 | O30: =M30+N30 -> 135155.83 | Q30: {=SUMPRODUCT(Data!$C$2:$C$10001,--(Data!$D$2:$D$10001=Information!Q$18),--(YEAR(Data!$B$2:$B$10001)=Information!$L30))} -> 0 | R30: {=SUMPRODUCT(Data!$C$2:$C$10001,--(Data!$D$2:$D$10001=Information!R$18),--(YEAR(Data!$B$2:$B$10001)=Information!$L30))} -> 0 | S30: {=SUMPRODUCT(Data!$C$2:$C$10001,--(Data!$D$2:$D$10001=Information!S$18),--(YEAR(Data!$B$2:$B$10001)=Information!$L30))} -> 0 | T30: =SUM(Q30:S30) -> 0
B31: Billed Usage (gallons): This is the usage that each household was billed for within the provider’s standard billing cycle (i.e., for each month) for calendar years around the rate structure change. | L31: 2025 | Q31: {=SUMPRODUCT(Data!$C$2:$C$10001,--(Data!$D$2:$D$10001=Information!Q$18),--(YEAR(Data!$B$2:$B$10001)=Information!$L31))} -> 0 | R31: {=SUMPRODUCT(Data!$C$2:$C$10001,--(Data!$D$2:$D$10001=Information!R$18),--(YEAR(Data!$B$2:$B$10001)=Information!$L31))} -> 0 | S31: {=SUMPRODUCT(Data!$C$2:$C$10001,--(Data!$D$2:$D$10001=Information!S$18),--(YEAR(Data!$B$2:$B$10001)=Information!$L31))} -> 0 | T31: =SUM(Q31:S31) -> 0
L32: Average | M32: =IFERROR(AVERAGEIF(M19:M31,"<>"&""),"") -> 120295.86 | N32: =IFERROR(AVERAGEIF(N19:N31,"<>"&""),"") -> 13307 | O32: =IFERROR(AVERAGEIF(O19:O31,"<>"&""),"") -> 133602.86 | P32: =IFERROR(AVERAGEIF(P19:P31,"<>"&""),"") | Q32: =IFERROR(AVERAGEIF(Q19:Q31,">0"),"") | R32: =IFERROR(AVERAGEIF(R19:R31,">0"),"") | S32: =IFERROR(AVERAGEIF(S19:S31,">0"),"") | T32: =IFERROR(AVERAGEIF(T19:T31,">0"),"")
L33: Total | M33: -- | P33: -- | Q33: =SUM(Q19:Q31) -> 0 | R33: =SUM(R19:R31) -> 0 | S33: =SUM(S19:S31) -> 0 | T33: =SUM(T19:T31) -> 0
B35: Record Date: Note the billing date (year-month-day or year-month). | L35: Account Types
L36: StrType | N36: Description
A37: To more effectively investigate the demand elasticity under different rate structures, we are additionally requesting the following optional information: | L37: A | N37: Residential SF Detached
L38: B | M38: B | N38: Residential SF Attached | O38: Residential SF Attached
L39: C | M39: C | N39: Apartments | O39: Apartments
B40: Residential Customer Category: You can optionally specify if the billed usage was for a Single Family, Multi Family, or SF and MF Combined residential consumer. This additional information will enable us to more accurately determine the usage and elasticity of indoor and outdoor water use, as well as being able to investigate trends in the elasticity based on the type of residential consumer. | L40: D | M40: D | N40: Townhomes/Trailers | O40: Townhomes/Trailers
L41: E | M41: E | N41: Business Commercial | O41: Business Commercial
L42: F | M42: F | N42: Industrial | O42: Industrial
L43: G | M43: G | N43: Wholesale | O43: Wholesale
L44: H | M44: H | N44: City Account | O44: City Account
L45: I | M45: I | N45: Residential Irrigation (e.g., HOA) | O45: Residential Irrigation (e.g., HOA)
L46: J | M46: J | N46: School/Church/Public | O46: School/Church/Public
L47: K | M47: K | N47: Reclaimed | O47: Reclaimed
...

Sheet Data
A1: Household Reference Number | B1: Record Date | C1: ="Billed Usage ("&Information!D6&")" -> Billed Usage (thousand gallons (kgal)) | D1: Residential Customer Category | E1: Notes (optional)
A2: 123 | B2: 45323 | C2: 100 | D2: =IFERROR(INDEX(Information!$N$37:$N$57,MATCH($A2,Information!$L$37:$L$57,0)),"") | E2: This is an example. Delete this and begin data entry on this row.
D3: =IFERROR(INDEX(Information!$N$37:$N$57,MATCH($A3,Information!$L$37:$L$57,0)),"")
D4: =IFERROR(INDEX(Information!$N$37:$N$57,MATCH($A4,Information!$L$37:$L$57,0)),"")
D5: =IFERROR(INDEX(Information!$N$37:$N$57,MATCH($A5,Information!$L$37:$L$57,0)),"")
D6: =IFERROR(INDEX(Information!$N$37:$N$57,MATCH($A6,Information!$L$37:$L$57,0)),"")
D7: =IFERROR(INDEX(Information!$N$37:$N$57,MATCH($A7,Information!$L$37:$L$57,0)),"")
D8: =IFERROR(INDEX(Information!$N$37:$N$57,MATCH($A8,Information!$L$37:$L$57,0)),"")
D9: =IFERROR(INDEX(Information!$N$37:$N$57,MATCH($A9,Information!$L$37:$L$57,0)),"")
D10: =IFERROR(INDEX(Information!$N$37:$N$57,MATCH($A10,Information!$L$37:$L$57,0)),"")
D11: =IFERROR(INDEX(Information!$N$37:$N$57,MATCH($A11,Information!$L$37:$L$57,0)),"")
D12: =IFERROR(INDEX(Information!$N$37:$N$57,MATCH($A12,Information!$L$37:$L$57,0)),"")
D13: =IFERROR(INDEX(Information!$N$37:$N$57,MATCH($A13,Information!$L$37:$L$57,0)),"")
D14: =IFERROR(INDEX(Information!$N$37:$N$57,MATCH($A14,Information!$L$37:$L$57,0)),"")
... D10001: =IFERROR(INDEX(Information!$N$37:$N$57,MATCH($A10001,Information!$L$37:$L$57,0)),"")
